[Mon Aug 28 14:55:53.583798 2017] [wsgi:error] [pid 3338:tid 140107554166528] [client 10.33.69.90:52301] mod_wsgi (pid=3338): Exception occurred processing WSGI script '/var/www/app/application/application.wsgi'.
[Mon Aug 28 14:55:53.583863 2017] [wsgi:error] [pid 3338:tid 140107554166528] [client 10.33.69.90:52301] Traceback (most recent call last):
[Mon Aug 28 14:55:53.583889 2017] [wsgi:error] [pid 3338:tid 140107554166528] [client 10.33.69.90:52301]   File "/var/www/app/application/application.wsgi", line 11, in application
[Mon Aug 28 14:55:53.583952 2017] [wsgi:error] [pid 3338:tid 140107554166528] [client 10.33.69.90:52301]     from mipaquete.mimodulo import mi_funcion_por_defecto
[Mon Aug 28 14:55:53.583976 2017] [wsgi:error] [pid 3338:tid 140107554166528] [client 10.33.69.90:52301] ImportError: No module named mipaquete.mimodulo
[Mon Aug 28 14:58:04.283811 2017] [wsgi:error] [pid 3444:tid 140273959036672] [client 10.33.69.90:52314] mod_wsgi (pid=3444, process='', application='app:8080|'): Failed to parse WSGI script file '/var/www/app/application/application.wsgi'.
[Mon Aug 28 14:58:04.283849 2017] [wsgi:error] [pid 3444:tid 140273959036672] [client 10.33.69.90:52314] mod_wsgi (pid=3444): Exception occurred processing WSGI script '/var/www/app/application/application.wsgi'.
[Mon Aug 28 14:58:04.283907 2017] [wsgi:error] [pid 3444:tid 140273959036672] [client 10.33.69.90:52314]   File "/var/www/app/application/application.wsgi", line 12
[Mon Aug 28 14:58:04.283921 2017] [wsgi:error] [pid 3444:tid 140273959036672] [client 10.33.69.90:52314]     output = "Hola mundo!"  #mi_funcion_por_defecto()
[Mon Aug 28 14:58:04.283928 2017] [wsgi:error] [pid 3444:tid 140273959036672] [client 10.33.69.90:52314]     ^
[Mon Aug 28 14:58:04.283935 2017] [wsgi:error] [pid 3444:tid 140273959036672] [client 10.33.69.90:52314] IndentationError: unexpected indent
[Mon Aug 28 14:58:04.398880 2017] [wsgi:error] [pid 3445:tid 140274070955776] [client 10.33.69.90:52313] mod_wsgi (pid=3445, process='', application='app:8080|'): Failed to parse WSGI script file '/var/www/app/application/application.wsgi'., referer: http://10.64.17.40:8080/
[Mon Aug 28 14:58:04.398909 2017] [wsgi:error] [pid 3445:tid 140274070955776] [client 10.33.69.90:52313] mod_wsgi (pid=3445): Exception occurred processing WSGI script '/var/www/app/application/application.wsgi'., referer: http://10.64.17.40:8080/
[Mon Aug 28 14:58:04.398963 2017] [wsgi:error] [pid 3445:tid 140274070955776] [client 10.33.69.90:52313]   File "/var/www/app/application/application.wsgi", line 12, referer: http://10.64.17.40:8080/
[Mon Aug 28 14:58:04.398978 2017] [wsgi:error] [pid 3445:tid 140274070955776] [client 10.33.69.90:52313]     output = "Hola mundo!"  #mi_funcion_por_defecto(), referer: http://10.64.17.40:8080/
[Mon Aug 28 14:58:04.398985 2017] [wsgi:error] [pid 3445:tid 140274070955776] [client 10.33.69.90:52313]     ^, referer: http://10.64.17.40:8080/
[Mon Aug 28 14:58:04.398992 2017] [wsgi:error] [pid 3445:tid 140274070955776] [client 10.33.69.90:52313] IndentationError: unexpected indent, referer: http://10.64.17.40:8080/
[Mon Aug 28 14:58:05.617628 2017] [wsgi:error] [pid 3444:tid 140273950643968] [client 10.33.69.90:52315] mod_wsgi (pid=3444, process='', application='app:8080|'): Failed to parse WSGI script file '/var/www/app/application/application.wsgi'.
[Mon Aug 28 14:58:05.617681 2017] [wsgi:error] [pid 3444:tid 140273950643968] [client 10.33.69.90:52315] mod_wsgi (pid=3444): Exception occurred processing WSGI script '/var/www/app/application/application.wsgi'.
[Mon Aug 28 14:58:05.617771 2017] [wsgi:error] [pid 3444:tid 140273950643968] [client 10.33.69.90:52315]   File "/var/www/app/application/application.wsgi", line 12
[Mon Aug 28 14:58:05.617785 2017] [wsgi:error] [pid 3444:tid 140273950643968] [client 10.33.69.90:52315]     output = "Hola mundo!"  #mi_funcion_por_defecto()
[Mon Aug 28 14:58:05.617792 2017] [wsgi:error] [pid 3444:tid 140273950643968] [client 10.33.69.90:52315]     ^
[Mon Aug 28 14:58:05.617799 2017] [wsgi:error] [pid 3444:tid 140273950643968] [client 10.33.69.90:52315] IndentationError: unexpected indent
[Mon Aug 28 14:58:05.675492 2017] [wsgi:error] [pid 3445:tid 140274062554880] [client 10.33.69.90:52317] mod_wsgi (pid=3445, process='', application='app:8080|'): Failed to parse WSGI script file '/var/www/app/application/application.wsgi'., referer: http://10.64.17.40:8080/
[Mon Aug 28 14:58:05.675526 2017] [wsgi:error] [pid 3445:tid 140274062554880] [client 10.33.69.90:52317] mod_wsgi (pid=3445): Exception occurred processing WSGI script '/var/www/app/application/application.wsgi'., referer: http://10.64.17.40:8080/
[Mon Aug 28 14:58:05.675591 2017] [wsgi:error] [pid 3445:tid 140274062554880] [client 10.33.69.90:52317]   File "/var/www/app/application/application.wsgi", line 12, referer: http://10.64.17.40:8080/
[Mon Aug 28 14:58:05.675606 2017] [wsgi:error] [pid 3445:tid 140274062554880] [client 10.33.69.90:52317]     output = "Hola mundo!"  #mi_funcion_por_defecto(), referer: http://10.64.17.40:8080/
[Mon Aug 28 14:58:05.675613 2017] [wsgi:error] [pid 3445:tid 140274062554880] [client 10.33.69.90:52317]     ^, referer: http://10.64.17.40:8080/
[Mon Aug 28 14:58:05.675619 2017] [wsgi:error] [pid 3445:tid 140274062554880] [client 10.33.69.90:52317] IndentationError: unexpected indent, referer: http://10.64.17.40:8080/
[Mon Aug 28 14:58:06.152705 2017] [wsgi:error] [pid 3445:tid 140274054153984] [client 10.33.69.90:52316] mod_wsgi (pid=3445, process='', application='app:8080|'): Failed to parse WSGI script file '/var/www/app/application/application.wsgi'.
[Mon Aug 28 14:58:06.152751 2017] [wsgi:error] [pid 3445:tid 140274054153984] [client 10.33.69.90:52316] mod_wsgi (pid=3445): Exception occurred processing WSGI script '/var/www/app/application/application.wsgi'.
[Mon Aug 28 14:58:06.152822 2017] [wsgi:error] [pid 3445:tid 140274054153984] [client 10.33.69.90:52316]   File "/var/www/app/application/application.wsgi", line 12
[Mon Aug 28 14:58:06.152838 2017] [wsgi:error] [pid 3445:tid 140274054153984] [client 10.33.69.90:52316]     output = "Hola mundo!"  #mi_funcion_por_defecto()
[Mon Aug 28 14:58:06.152845 2017] [wsgi:error] [pid 3445:tid 140274054153984] [client 10.33.69.90:52316]     ^
[Mon Aug 28 14:58:06.152851 2017] [wsgi:error] [pid 3445:tid 140274054153984] [client 10.33.69.90:52316] IndentationError: unexpected indent
[Mon Aug 28 14:58:06.210451 2017] [wsgi:error] [pid 3444:tid 140273942251264] [client 10.33.69.90:52319] mod_wsgi (pid=3444, process='', application='app:8080|'): Failed to parse WSGI script file '/var/www/app/application/application.wsgi'., referer: http://10.64.17.40:8080/
[Mon Aug 28 14:58:06.210479 2017] [wsgi:error] [pid 3444:tid 140273942251264] [client 10.33.69.90:52319] mod_wsgi (pid=3444): Exception occurred processing WSGI script '/var/www/app/application/application.wsgi'., referer: http://10.64.17.40:8080/
[Mon Aug 28 14:58:06.210530 2017] [wsgi:error] [pid 3444:tid 140273942251264] [client 10.33.69.90:52319]   File "/var/www/app/application/application.wsgi", line 12, referer: http://10.64.17.40:8080/
[Mon Aug 28 14:58:06.210544 2017] [wsgi:error] [pid 3444:tid 140273942251264] [client 10.33.69.90:52319]     output = "Hola mundo!"  #mi_funcion_por_defecto(), referer: http://10.64.17.40:8080/
[Mon Aug 28 14:58:06.210551 2017] [wsgi:error] [pid 3444:tid 140273942251264] [client 10.33.69.90:52319]     ^, referer: http://10.64.17.40:8080/
[Mon Aug 28 14:58:06.210558 2017] [wsgi:error] [pid 3444:tid 140273942251264] [client 10.33.69.90:52319] IndentationError: unexpected indent, referer: http://10.64.17.40:8080/
[Mon Aug 28 14:58:06.512971 2017] [wsgi:error] [pid 3445:tid 140274045753088] [client 10.33.69.90:52318] mod_wsgi (pid=3445, process='', application='app:8080|'): Failed to parse WSGI script file '/var/www/app/application/application.wsgi'.
[Mon Aug 28 14:58:06.512993 2017] [wsgi:error] [pid 3445:tid 140274045753088] [client 10.33.69.90:52318] mod_wsgi (pid=3445): Exception occurred processing WSGI script '/var/www/app/application/application.wsgi'.
[Mon Aug 28 14:58:06.513048 2017] [wsgi:error] [pid 3445:tid 140274045753088] [client 10.33.69.90:52318]   File "/var/www/app/application/application.wsgi", line 12
[Mon Aug 28 14:58:06.513075 2017] [wsgi:error] [pid 3445:tid 140274045753088] [client 10.33.69.90:52318]     output = "Hola mundo!"  #mi_funcion_por_defecto()
[Mon Aug 28 14:58:06.513082 2017] [wsgi:error] [pid 3445:tid 140274045753088] [client 10.33.69.90:52318]     ^
[Mon Aug 28 14:58:06.513088 2017] [wsgi:error] [pid 3445:tid 140274045753088] [client 10.33.69.90:52318] IndentationError: unexpected indent
[Mon Aug 28 14:58:06.578786 2017] [wsgi:error] [pid 3444:tid 140273933858560] [client 10.33.69.90:52321] mod_wsgi (pid=3444, process='', application='app:8080|'): Failed to parse WSGI script file '/var/www/app/application/application.wsgi'., referer: http://10.64.17.40:8080/
[Mon Aug 28 14:58:06.578807 2017] [wsgi:error] [pid 3444:tid 140273933858560] [client 10.33.69.90:52321] mod_wsgi (pid=3444): Exception occurred processing WSGI script '/var/www/app/application/application.wsgi'., referer: http://10.64.17.40:8080/
[Mon Aug 28 14:58:06.578860 2017] [wsgi:error] [pid 3444:tid 140273933858560] [client 10.33.69.90:52321]   File "/var/www/app/application/application.wsgi", line 12, referer: http://10.64.17.40:8080/
[Mon Aug 28 14:58:06.578877 2017] [wsgi:error] [pid 3444:tid 140273933858560] [client 10.33.69.90:52321]     output = "Hola mundo!"  #mi_funcion_por_defecto(), referer: http://10.64.17.40:8080/
[Mon Aug 28 14:58:06.578884 2017] [wsgi:error] [pid 3444:tid 140273933858560] [client 10.33.69.90:52321]     ^, referer: http://10.64.17.40:8080/
[Mon Aug 28 14:58:06.578891 2017] [wsgi:error] [pid 3444:tid 140273933858560] [client 10.33.69.90:52321] IndentationError: unexpected indent, referer: http://10.64.17.40:8080/
[Mon Aug 28 14:58:06.792261 2017] [wsgi:error] [pid 3445:tid 140273967429376] [client 10.33.69.90:52320] mod_wsgi (pid=3445, process='', application='app:8080|'): Failed to parse WSGI script file '/var/www/app/application/application.wsgi'.
[Mon Aug 28 14:58:06.792282 2017] [wsgi:error] [pid 3445:tid 140273967429376] [client 10.33.69.90:52320] mod_wsgi (pid=3445): Exception occurred processing WSGI script '/var/www/app/application/application.wsgi'.
[Mon Aug 28 14:58:06.792331 2017] [wsgi:error] [pid 3445:tid 140273967429376] [client 10.33.69.90:52320]   File "/var/www/app/application/application.wsgi", line 12
[Mon Aug 28 14:58:06.792365 2017] [wsgi:error] [pid 3445:tid 140273967429376] [client 10.33.69.90:52320]     output = "Hola mundo!"  #mi_funcion_por_defecto()
[Mon Aug 28 14:58:06.792375 2017] [wsgi:error] [pid 3445:tid 140273967429376] [client 10.33.69.90:52320]     ^
[Mon Aug 28 14:58:06.792381 2017] [wsgi:error] [pid 3445:tid 140273967429376] [client 10.33.69.90:52320] IndentationError: unexpected indent
[Mon Aug 28 14:58:06.857453 2017] [wsgi:error] [pid 3444:tid 140273925465856] [client 10.33.69.90:52323] mod_wsgi (pid=3444, process='', application='app:8080|'): Failed to parse WSGI script file '/var/www/app/application/application.wsgi'., referer: http://10.64.17.40:8080/
[Mon Aug 28 14:58:06.857474 2017] [wsgi:error] [pid 3444:tid 140273925465856] [client 10.33.69.90:52323] mod_wsgi (pid=3444): Exception occurred processing WSGI script '/var/www/app/application/application.wsgi'., referer: http://10.64.17.40:8080/
[Mon Aug 28 14:58:06.857523 2017] [wsgi:error] [pid 3444:tid 140273925465856] [client 10.33.69.90:52323]   File "/var/www/app/application/application.wsgi", line 12, referer: http://10.64.17.40:8080/
[Mon Aug 28 14:58:06.857540 2017] [wsgi:error] [pid 3444:tid 140273925465856] [client 10.33.69.90:52323]     output = "Hola mundo!"  #mi_funcion_por_defecto(), referer: http://10.64.17.40:8080/
[Mon Aug 28 14:58:06.857547 2017] [wsgi:error] [pid 3444:tid 140273925465856] [client 10.33.69.90:52323]     ^, referer: http://10.64.17.40:8080/
[Mon Aug 28 14:58:06.857553 2017] [wsgi:error] [pid 3444:tid 140273925465856] [client 10.33.69.90:52323] IndentationError: unexpected indent, referer: http://10.64.17.40:8080/
[Mon Aug 28 14:58:07.022041 2017] [wsgi:error] [pid 3445:tid 140273959036672] [client 10.33.69.90:52322] mod_wsgi (pid=3445, process='', application='app:8080|'): Failed to parse WSGI script file '/var/www/app/application/application.wsgi'.
[Mon Aug 28 14:58:07.022078 2017] [wsgi:error] [pid 3445:tid 140273959036672] [client 10.33.69.90:52322] mod_wsgi (pid=3445): Exception occurred processing WSGI script '/var/www/app/application/application.wsgi'.
[Mon Aug 28 14:58:07.022130 2017] [wsgi:error] [pid 3445:tid 140273959036672] [client 10.33.69.90:52322]   File "/var/www/app/application/application.wsgi", line 12
[Mon Aug 28 14:58:07.022143 2017] [wsgi:error] [pid 3445:tid 140273959036672] [client 10.33.69.90:52322]     output = "Hola mundo!"  #mi_funcion_por_defecto()
[Mon Aug 28 14:58:07.022150 2017] [wsgi:error] [pid 3445:tid 140273959036672] [client 10.33.69.90:52322]     ^
[Mon Aug 28 14:58:07.022156 2017] [wsgi:error] [pid 3445:tid 140273959036672] [client 10.33.69.90:52322] IndentationError: unexpected indent
[Mon Aug 28 14:58:07.073646 2017] [wsgi:error] [pid 3445:tid 140273950643968] [client 10.33.69.90:52325] mod_wsgi (pid=3445, process='', application='app:8080|'): Failed to parse WSGI script file '/var/www/app/application/application.wsgi'., referer: http://10.64.17.40:8080/
[Mon Aug 28 14:58:07.073667 2017] [wsgi:error] [pid 3445:tid 140273950643968] [client 10.33.69.90:52325] mod_wsgi (pid=3445): Exception occurred processing WSGI script '/var/www/app/application/application.wsgi'., referer: http://10.64.17.40:8080/
[Mon Aug 28 14:58:07.073716 2017] [wsgi:error] [pid 3445:tid 140273950643968] [client 10.33.69.90:52325]   File "/var/www/app/application/application.wsgi", line 12, referer: http://10.64.17.40:8080/
[Mon Aug 28 14:58:07.073733 2017] [wsgi:error] [pid 3445:tid 140273950643968] [client 10.33.69.90:52325]     output = "Hola mundo!"  #mi_funcion_por_defecto(), referer: http://10.64.17.40:8080/
[Mon Aug 28 14:58:07.073740 2017] [wsgi:error] [pid 3445:tid 140273950643968] [client 10.33.69.90:52325]     ^, referer: http://10.64.17.40:8080/
[Mon Aug 28 14:58:07.073746 2017] [wsgi:error] [pid 3445:tid 140273950643968] [client 10.33.69.90:52325] IndentationError: unexpected indent, referer: http://10.64.17.40:8080/
[Mon Aug 28 14:58:07.223438 2017] [wsgi:error] [pid 3444:tid 140273967429376] [client 10.33.69.90:52324] mod_wsgi (pid=3444, process='', application='app:8080|'): Failed to parse WSGI script file '/var/www/app/application/application.wsgi'.
[Mon Aug 28 14:58:07.223465 2017] [wsgi:error] [pid 3444:tid 140273967429376] [client 10.33.69.90:52324] mod_wsgi (pid=3444): Exception occurred processing WSGI script '/var/www/app/application/application.wsgi'.
[Mon Aug 28 14:58:07.223517 2017] [wsgi:error] [pid 3444:tid 140273967429376] [client 10.33.69.90:52324]   File "/var/www/app/application/application.wsgi", line 12
[Mon Aug 28 14:58:07.223530 2017] [wsgi:error] [pid 3444:tid 140273967429376] [client 10.33.69.90:52324]     output = "Hola mundo!"  #mi_funcion_por_defecto()
[Mon Aug 28 14:58:07.223537 2017] [wsgi:error] [pid 3444:tid 140273967429376] [client 10.33.69.90:52324]     ^
[Mon Aug 28 14:58:07.223543 2017] [wsgi:error] [pid 3444:tid 140273967429376] [client 10.33.69.90:52324] IndentationError: unexpected indent
[Mon Aug 28 14:58:07.283500 2017] [wsgi:error] [pid 3444:tid 140273917073152] [client 10.33.69.90:52327] mod_wsgi (pid=3444, process='', application='app:8080|'): Failed to parse WSGI script file '/var/www/app/application/application.wsgi'., referer: http://10.64.17.40:8080/
[Mon Aug 28 14:58:07.283520 2017] [wsgi:error] [pid 3444:tid 140273917073152] [client 10.33.69.90:52327] mod_wsgi (pid=3444): Exception occurred processing WSGI script '/var/www/app/application/application.wsgi'., referer: http://10.64.17.40:8080/
[Mon Aug 28 14:58:07.283570 2017] [wsgi:error] [pid 3444:tid 140273917073152] [client 10.33.69.90:52327]   File "/var/www/app/application/application.wsgi", line 12, referer: http://10.64.17.40:8080/
[Mon Aug 28 14:58:07.283587 2017] [wsgi:error] [pid 3444:tid 140273917073152] [client 10.33.69.90:52327]     output = "Hola mundo!"  #mi_funcion_por_defecto(), referer: http://10.64.17.40:8080/
[Mon Aug 28 14:58:07.283601 2017] [wsgi:error] [pid 3444:tid 140273917073152] [client 10.33.69.90:52327]     ^, referer: http://10.64.17.40:8080/
[Mon Aug 28 14:58:07.283608 2017] [wsgi:error] [pid 3444:tid 140273917073152] [client 10.33.69.90:52327] IndentationError: unexpected indent, referer: http://10.64.17.40:8080/
[Mon Aug 28 15:30:33.835209 2017] [wsgi:error] [pid 3712:tid 140375293421312] [client 10.33.69.90:52735] mod_wsgi (pid=3712): Exception occurred processing WSGI script '/var/www/app/application/application.wsgi'.
[Mon Aug 28 15:30:33.835263 2017] [wsgi:error] [pid 3712:tid 140375293421312] [client 10.33.69.90:52735] Traceback (most recent call last):
[Mon Aug 28 15:30:33.835285 2017] [wsgi:error] [pid 3712:tid 140375293421312] [client 10.33.69.90:52735]   File "/var/www/app/application/application.wsgi", line 8, in application
[Mon Aug 28 15:30:33.835340 2017] [wsgi:error] [pid 3712:tid 140375293421312] [client 10.33.69.90:52735]     from application.prueba import mi_funcion
[Mon Aug 28 15:30:33.835362 2017] [wsgi:error] [pid 3712:tid 140375293421312] [client 10.33.69.90:52735] ImportError: No module named application.prueba
[Mon Aug 28 15:30:33.967346 2017] [wsgi:error] [pid 3711:tid 140375293421312] [client 10.33.69.90:52734] mod_wsgi (pid=3711): Exception occurred processing WSGI script '/var/www/app/application/application.wsgi'., referer: http://10.64.17.40:8080/
[Mon Aug 28 15:30:33.967383 2017] [wsgi:error] [pid 3711:tid 140375293421312] [client 10.33.69.90:52734] Traceback (most recent call last):, referer: http://10.64.17.40:8080/
[Mon Aug 28 15:30:33.967402 2017] [wsgi:error] [pid 3711:tid 140375293421312] [client 10.33.69.90:52734]   File "/var/www/app/application/application.wsgi", line 8, in application, referer: http://10.64.17.40:8080/
[Mon Aug 28 15:30:33.967457 2017] [wsgi:error] [pid 3711:tid 140375293421312] [client 10.33.69.90:52734]     from application.prueba import mi_funcion, referer: http://10.64.17.40:8080/
[Mon Aug 28 15:30:33.967479 2017] [wsgi:error] [pid 3711:tid 140375293421312] [client 10.33.69.90:52734] ImportError: No module named application.prueba, referer: http://10.64.17.40:8080/
[Mon Aug 28 15:36:50.849391 2017] [wsgi:error] [pid 3844:tid 139886011086592] [client 10.33.69.90:52878] mod_wsgi (pid=3844): Exception occurred processing WSGI script '/var/www/app/application/application.wsgi'.
[Mon Aug 28 15:36:50.849446 2017] [wsgi:error] [pid 3844:tid 139886011086592] [client 10.33.69.90:52878] Traceback (most recent call last):
[Mon Aug 28 15:36:50.849467 2017] [wsgi:error] [pid 3844:tid 139886011086592] [client 10.33.69.90:52878]   File "/var/www/app/application/application.wsgi", line 8, in application
[Mon Aug 28 15:36:50.849521 2017] [wsgi:error] [pid 3844:tid 139886011086592] [client 10.33.69.90:52878]     from application.modulos_python.prueba import mi_funcion
[Mon Aug 28 15:36:50.849543 2017] [wsgi:error] [pid 3844:tid 139886011086592] [client 10.33.69.90:52878] ImportError: No module named application.modulos_python.prueba
[Mon Aug 28 15:36:50.965070 2017] [wsgi:error] [pid 3843:tid 139885918766848] [client 10.33.69.90:52879] mod_wsgi (pid=3843): Exception occurred processing WSGI script '/var/www/app/application/application.wsgi'., referer: http://10.64.17.40:8080/
[Mon Aug 28 15:36:50.965105 2017] [wsgi:error] [pid 3843:tid 139885918766848] [client 10.33.69.90:52879] Traceback (most recent call last):, referer: http://10.64.17.40:8080/
[Mon Aug 28 15:36:50.965125 2017] [wsgi:error] [pid 3843:tid 139885918766848] [client 10.33.69.90:52879]   File "/var/www/app/application/application.wsgi", line 8, in application, referer: http://10.64.17.40:8080/
[Mon Aug 28 15:36:50.965178 2017] [wsgi:error] [pid 3843:tid 139885918766848] [client 10.33.69.90:52879]     from application.modulos_python.prueba import mi_funcion, referer: http://10.64.17.40:8080/
[Mon Aug 28 15:36:50.965200 2017] [wsgi:error] [pid 3843:tid 139885918766848] [client 10.33.69.90:52879] ImportError: No module named application.modulos_python.prueba, referer: http://10.64.17.40:8080/
[Mon Aug 28 15:36:54.638708 2017] [wsgi:error] [pid 3843:tid 139885901981440] [client 10.33.69.90:52880] mod_wsgi (pid=3843): Exception occurred processing WSGI script '/var/www/app/application/application.wsgi'.
[Mon Aug 28 15:36:54.638770 2017] [wsgi:error] [pid 3843:tid 139885901981440] [client 10.33.69.90:52880] Traceback (most recent call last):
[Mon Aug 28 15:36:54.638800 2017] [wsgi:error] [pid 3843:tid 139885901981440] [client 10.33.69.90:52880]   File "/var/www/app/application/application.wsgi", line 8, in application
[Mon Aug 28 15:36:54.638838 2017] [wsgi:error] [pid 3843:tid 139885901981440] [client 10.33.69.90:52880]     from application.modulos_python.prueba import mi_funcion
[Mon Aug 28 15:36:54.638862 2017] [wsgi:error] [pid 3843:tid 139885901981440] [client 10.33.69.90:52880] ImportError: No module named application.modulos_python.prueba
[Mon Aug 28 15:36:54.770539 2017] [wsgi:error] [pid 3843:tid 139886011086592] [client 10.33.69.90:52882] mod_wsgi (pid=3843): Exception occurred processing WSGI script '/var/www/app/application/application.wsgi'., referer: http://10.64.17.40:8080/
[Mon Aug 28 15:36:54.770568 2017] [wsgi:error] [pid 3843:tid 139886011086592] [client 10.33.69.90:52882] Traceback (most recent call last):, referer: http://10.64.17.40:8080/
[Mon Aug 28 15:36:54.770588 2017] [wsgi:error] [pid 3843:tid 139886011086592] [client 10.33.69.90:52882]   File "/var/www/app/application/application.wsgi", line 8, in application, referer: http://10.64.17.40:8080/
[Mon Aug 28 15:36:54.770612 2017] [wsgi:error] [pid 3843:tid 139886011086592] [client 10.33.69.90:52882]     from application.modulos_python.prueba import mi_funcion, referer: http://10.64.17.40:8080/
[Mon Aug 28 15:36:54.770630 2017] [wsgi:error] [pid 3843:tid 139886011086592] [client 10.33.69.90:52882] ImportError: No module named application.modulos_python.prueba, referer: http://10.64.17.40:8080/
[Mon Aug 28 15:41:12.710535 2017] [wsgi:error] [pid 3951:tid 139882276296448] [client 10.33.69.90:52929] mod_wsgi (pid=3951): Exception occurred processing WSGI script '/var/www/app/application/application.wsgi'.
[Mon Aug 28 15:41:12.710591 2017] [wsgi:error] [pid 3951:tid 139882276296448] [client 10.33.69.90:52929] Traceback (most recent call last):
[Mon Aug 28 15:41:12.710614 2017] [wsgi:error] [pid 3951:tid 139882276296448] [client 10.33.69.90:52929]   File "/var/www/app/application/application.wsgi", line 8, in application
[Mon Aug 28 15:41:12.710675 2017] [wsgi:error] [pid 3951:tid 139882276296448] [client 10.33.69.90:52929]     from app.application.modulos_python.prueba import mi_funcion
[Mon Aug 28 15:41:12.710700 2017] [wsgi:error] [pid 3951:tid 139882276296448] [client 10.33.69.90:52929] ImportError: No module named app.application.modulos_python.prueba
[Mon Aug 28 15:41:12.786079 2017] [wsgi:error] [pid 3950:tid 139882093561600] [client 10.33.69.90:52930] mod_wsgi (pid=3950): Exception occurred processing WSGI script '/var/www/app/application/application.wsgi'., referer: http://10.64.17.40:8080/
[Mon Aug 28 15:41:12.786116 2017] [wsgi:error] [pid 3950:tid 139882093561600] [client 10.33.69.90:52930] Traceback (most recent call last):, referer: http://10.64.17.40:8080/
[Mon Aug 28 15:41:12.786137 2017] [wsgi:error] [pid 3950:tid 139882093561600] [client 10.33.69.90:52930]   File "/var/www/app/application/application.wsgi", line 8, in application, referer: http://10.64.17.40:8080/
[Mon Aug 28 15:41:12.786196 2017] [wsgi:error] [pid 3950:tid 139882093561600] [client 10.33.69.90:52930]     from app.application.modulos_python.prueba import mi_funcion, referer: http://10.64.17.40:8080/
[Mon Aug 28 15:41:12.786222 2017] [wsgi:error] [pid 3950:tid 139882093561600] [client 10.33.69.90:52930] ImportError: No module named app.application.modulos_python.prueba, referer: http://10.64.17.40:8080/
[Mon Aug 28 15:42:08.381864 2017] [wsgi:error] [pid 4061:tid 140301733680896] [client 10.33.69.90:52937] mod_wsgi (pid=4061): Exception occurred processing WSGI script '/var/www/app/application/application.wsgi'.
[Mon Aug 28 15:42:08.381916 2017] [wsgi:error] [pid 4061:tid 140301733680896] [client 10.33.69.90:52937] Traceback (most recent call last):
[Mon Aug 28 15:42:08.381949 2017] [wsgi:error] [pid 4061:tid 140301733680896] [client 10.33.69.90:52937]   File "/var/www/app/application/application.wsgi", line 8, in application
[Mon Aug 28 15:42:08.382005 2017] [wsgi:error] [pid 4061:tid 140301733680896] [client 10.33.69.90:52937]     from modulos_python.prueba import mi_funcion
[Mon Aug 28 15:42:08.382026 2017] [wsgi:error] [pid 4061:tid 140301733680896] [client 10.33.69.90:52937] ImportError: No module named modulos_python.prueba
[Mon Aug 28 15:42:08.503153 2017] [wsgi:error] [pid 4062:tid 140301800822528] [client 10.33.69.90:52939] mod_wsgi (pid=4062): Exception occurred processing WSGI script '/var/www/app/application/application.wsgi'., referer: http://10.64.17.40:8080/
[Mon Aug 28 15:42:08.503197 2017] [wsgi:error] [pid 4062:tid 140301800822528] [client 10.33.69.90:52939] Traceback (most recent call last):, referer: http://10.64.17.40:8080/
[Mon Aug 28 15:42:08.503217 2017] [wsgi:error] [pid 4062:tid 140301800822528] [client 10.33.69.90:52939]   File "/var/www/app/application/application.wsgi", line 8, in application, referer: http://10.64.17.40:8080/
[Mon Aug 28 15:42:08.503270 2017] [wsgi:error] [pid 4062:tid 140301800822528] [client 10.33.69.90:52939]     from modulos_python.prueba import mi_funcion, referer: http://10.64.17.40:8080/
[Mon Aug 28 15:42:08.503292 2017] [wsgi:error] [pid 4062:tid 140301800822528] [client 10.33.69.90:52939] ImportError: No module named modulos_python.prueba, referer: http://10.64.17.40:8080/
[Mon Aug 28 15:42:09.107459 2017] [wsgi:error] [pid 4061:tid 140301725288192] [client 10.33.69.90:52938] mod_wsgi (pid=4061): Exception occurred processing WSGI script '/var/www/app/application/application.wsgi'.
[Mon Aug 28 15:42:09.107501 2017] [wsgi:error] [pid 4061:tid 140301725288192] [client 10.33.69.90:52938] Traceback (most recent call last):
[Mon Aug 28 15:42:09.107525 2017] [wsgi:error] [pid 4061:tid 140301725288192] [client 10.33.69.90:52938]   File "/var/www/app/application/application.wsgi", line 8, in application
[Mon Aug 28 15:42:09.107573 2017] [wsgi:error] [pid 4061:tid 140301725288192] [client 10.33.69.90:52938]     from modulos_python.prueba import mi_funcion
[Mon Aug 28 15:42:09.107596 2017] [wsgi:error] [pid 4061:tid 140301725288192] [client 10.33.69.90:52938] ImportError: No module named modulos_python.prueba
[Mon Aug 28 15:42:09.174198 2017] [wsgi:error] [pid 4062:tid 140301792429824] [client 10.33.69.90:52940] mod_wsgi (pid=4062): Exception occurred processing WSGI script '/var/www/app/application/application.wsgi'., referer: http://10.64.17.40:8080/
[Mon Aug 28 15:42:09.174233 2017] [wsgi:error] [pid 4062:tid 140301792429824] [client 10.33.69.90:52940] Traceback (most recent call last):, referer: http://10.64.17.40:8080/
[Mon Aug 28 15:42:09.174254 2017] [wsgi:error] [pid 4062:tid 140301792429824] [client 10.33.69.90:52940]   File "/var/www/app/application/application.wsgi", line 8, in application, referer: http://10.64.17.40:8080/
[Mon Aug 28 15:42:09.174279 2017] [wsgi:error] [pid 4062:tid 140301792429824] [client 10.33.69.90:52940]     from modulos_python.prueba import mi_funcion, referer: http://10.64.17.40:8080/
[Mon Aug 28 15:42:09.174297 2017] [wsgi:error] [pid 4062:tid 140301792429824] [client 10.33.69.90:52940] ImportError: No module named modulos_python.prueba, referer: http://10.64.17.40:8080/
[Mon Aug 28 15:42:09.547377 2017] [wsgi:error] [pid 4061:tid 140301716895488] [client 10.33.69.90:52941] mod_wsgi (pid=4061): Exception occurred processing WSGI script '/var/www/app/application/application.wsgi'.
[Mon Aug 28 15:42:09.547407 2017] [wsgi:error] [pid 4061:tid 140301716895488] [client 10.33.69.90:52941] Traceback (most recent call last):
[Mon Aug 28 15:42:09.547428 2017] [wsgi:error] [pid 4061:tid 140301716895488] [client 10.33.69.90:52941]   File "/var/www/app/application/application.wsgi", line 8, in application
[Mon Aug 28 15:42:09.547453 2017] [wsgi:error] [pid 4061:tid 140301716895488] [client 10.33.69.90:52941]     from modulos_python.prueba import mi_funcion
[Mon Aug 28 15:42:09.547478 2017] [wsgi:error] [pid 4061:tid 140301716895488] [client 10.33.69.90:52941] ImportError: No module named modulos_python.prueba
[Mon Aug 28 15:42:09.605443 2017] [wsgi:error] [pid 4062:tid 140301784037120] [client 10.33.69.90:52942] mod_wsgi (pid=4062): Exception occurred processing WSGI script '/var/www/app/application/application.wsgi'., referer: http://10.64.17.40:8080/
[Mon Aug 28 15:42:09.605472 2017] [wsgi:error] [pid 4062:tid 140301784037120] [client 10.33.69.90:52942] Traceback (most recent call last):, referer: http://10.64.17.40:8080/
[Mon Aug 28 15:42:09.605493 2017] [wsgi:error] [pid 4062:tid 140301784037120] [client 10.33.69.90:52942]   File "/var/www/app/application/application.wsgi", line 8, in application, referer: http://10.64.17.40:8080/
[Mon Aug 28 15:42:09.605518 2017] [wsgi:error] [pid 4062:tid 140301784037120] [client 10.33.69.90:52942]     from modulos_python.prueba import mi_funcion, referer: http://10.64.17.40:8080/
[Mon Aug 28 15:42:09.605536 2017] [wsgi:error] [pid 4062:tid 140301784037120] [client 10.33.69.90:52942] ImportError: No module named modulos_python.prueba, referer: http://10.64.17.40:8080/
[Mon Aug 28 15:42:09.827380 2017] [wsgi:error] [pid 4061:tid 140301708502784] [client 10.33.69.90:52943] mod_wsgi (pid=4061): Exception occurred processing WSGI script '/var/www/app/application/application.wsgi'.
[Mon Aug 28 15:42:09.827409 2017] [wsgi:error] [pid 4061:tid 140301708502784] [client 10.33.69.90:52943] Traceback (most recent call last):
[Mon Aug 28 15:42:09.827429 2017] [wsgi:error] [pid 4061:tid 140301708502784] [client 10.33.69.90:52943]   File "/var/www/app/application/application.wsgi", line 8, in application
[Mon Aug 28 15:42:09.827453 2017] [wsgi:error] [pid 4061:tid 140301708502784] [client 10.33.69.90:52943]     from modulos_python.prueba import mi_funcion
[Mon Aug 28 15:42:09.827470 2017] [wsgi:error] [pid 4061:tid 140301708502784] [client 10.33.69.90:52943] ImportError: No module named modulos_python.prueba
[Mon Aug 28 15:42:09.891282 2017] [wsgi:error] [pid 4061:tid 140301691717376] [client 10.33.69.90:52945] mod_wsgi (pid=4061): Exception occurred processing WSGI script '/var/www/app/application/application.wsgi'., referer: http://10.64.17.40:8080/
[Mon Aug 28 15:42:09.891312 2017] [wsgi:error] [pid 4061:tid 140301691717376] [client 10.33.69.90:52945] Traceback (most recent call last):, referer: http://10.64.17.40:8080/
[Mon Aug 28 15:42:09.891332 2017] [wsgi:error] [pid 4061:tid 140301691717376] [client 10.33.69.90:52945]   File "/var/www/app/application/application.wsgi", line 8, in application, referer: http://10.64.17.40:8080/
[Mon Aug 28 15:42:09.891357 2017] [wsgi:error] [pid 4061:tid 140301691717376] [client 10.33.69.90:52945]     from modulos_python.prueba import mi_funcion, referer: http://10.64.17.40:8080/
[Mon Aug 28 15:42:09.891374 2017] [wsgi:error] [pid 4061:tid 140301691717376] [client 10.33.69.90:52945] ImportError: No module named modulos_python.prueba, referer: http://10.64.17.40:8080/
[Mon Aug 28 15:44:47.335942 2017] [wsgi:error] [pid 4166:tid 140650766915328] [client 10.33.69.90:52964] mod_wsgi (pid=4166): Exception occurred processing WSGI script '/var/www/app/application/application.wsgi'.
[Mon Aug 28 15:44:47.336005 2017] [wsgi:error] [pid 4166:tid 140650766915328] [client 10.33.69.90:52964] Traceback (most recent call last):
[Mon Aug 28 15:44:47.336027 2017] [wsgi:error] [pid 4166:tid 140650766915328] [client 10.33.69.90:52964]   File "/var/www/app/application/application.wsgi", line 8, in application
[Mon Aug 28 15:44:47.336082 2017] [wsgi:error] [pid 4166:tid 140650766915328] [client 10.33.69.90:52964]     import application.modulos_python.prueba
[Mon Aug 28 15:44:47.336104 2017] [wsgi:error] [pid 4166:tid 140650766915328] [client 10.33.69.90:52964] ImportError: No module named application.modulos_python.prueba
[Mon Aug 28 15:44:47.470406 2017] [wsgi:error] [pid 4167:tid 140650766915328] [client 10.33.69.90:52965] mod_wsgi (pid=4167): Exception occurred processing WSGI script '/var/www/app/application/application.wsgi'., referer: http://10.64.17.40:8080/
[Mon Aug 28 15:44:47.470456 2017] [wsgi:error] [pid 4167:tid 140650766915328] [client 10.33.69.90:52965] Traceback (most recent call last):, referer: http://10.64.17.40:8080/
[Mon Aug 28 15:44:47.470476 2017] [wsgi:error] [pid 4167:tid 140650766915328] [client 10.33.69.90:52965]   File "/var/www/app/application/application.wsgi", line 8, in application, referer: http://10.64.17.40:8080/
[Mon Aug 28 15:44:47.470530 2017] [wsgi:error] [pid 4167:tid 140650766915328] [client 10.33.69.90:52965]     import application.modulos_python.prueba, referer: http://10.64.17.40:8080/
[Mon Aug 28 15:44:47.470553 2017] [wsgi:error] [pid 4167:tid 140650766915328] [client 10.33.69.90:52965] ImportError: No module named application.modulos_python.prueba, referer: http://10.64.17.40:8080/
[Mon Aug 28 15:44:48.238118 2017] [wsgi:error] [pid 4166:tid 140650758522624] [client 10.33.69.90:52966] mod_wsgi (pid=4166): Exception occurred processing WSGI script '/var/www/app/application/application.wsgi'.
[Mon Aug 28 15:44:48.238171 2017] [wsgi:error] [pid 4166:tid 140650758522624] [client 10.33.69.90:52966] Traceback (most recent call last):
[Mon Aug 28 15:44:48.238200 2017] [wsgi:error] [pid 4166:tid 140650758522624] [client 10.33.69.90:52966]   File "/var/www/app/application/application.wsgi", line 8, in application
[Mon Aug 28 15:44:48.238237 2017] [wsgi:error] [pid 4166:tid 140650758522624] [client 10.33.69.90:52966]     import application.modulos_python.prueba
[Mon Aug 28 15:44:48.238260 2017] [wsgi:error] [pid 4166:tid 140650758522624] [client 10.33.69.90:52966] ImportError: No module named application.modulos_python.prueba
[Mon Aug 28 15:44:48.303987 2017] [wsgi:error] [pid 4167:tid 140650758522624] [client 10.33.69.90:52968] mod_wsgi (pid=4167): Exception occurred processing WSGI script '/var/www/app/application/application.wsgi'., referer: http://10.64.17.40:8080/
[Mon Aug 28 15:44:48.304023 2017] [wsgi:error] [pid 4167:tid 140650758522624] [client 10.33.69.90:52968] Traceback (most recent call last):, referer: http://10.64.17.40:8080/
[Mon Aug 28 15:44:48.304047 2017] [wsgi:error] [pid 4167:tid 140650758522624] [client 10.33.69.90:52968]   File "/var/www/app/application/application.wsgi", line 8, in application, referer: http://10.64.17.40:8080/
[Mon Aug 28 15:44:48.304078 2017] [wsgi:error] [pid 4167:tid 140650758522624] [client 10.33.69.90:52968]     import application.modulos_python.prueba, referer: http://10.64.17.40:8080/
[Mon Aug 28 15:44:48.304100 2017] [wsgi:error] [pid 4167:tid 140650758522624] [client 10.33.69.90:52968] ImportError: No module named application.modulos_python.prueba, referer: http://10.64.17.40:8080/
[Mon Aug 28 15:44:48.645734 2017] [wsgi:error] [pid 4166:tid 140650750129920] [client 10.33.69.90:52967] mod_wsgi (pid=4166): Exception occurred processing WSGI script '/var/www/app/application/application.wsgi'.
[Mon Aug 28 15:44:48.645762 2017] [wsgi:error] [pid 4166:tid 140650750129920] [client 10.33.69.90:52967] Traceback (most recent call last):
[Mon Aug 28 15:44:48.645783 2017] [wsgi:error] [pid 4166:tid 140650750129920] [client 10.33.69.90:52967]   File "/var/www/app/application/application.wsgi", line 8, in application
[Mon Aug 28 15:44:48.645819 2017] [wsgi:error] [pid 4166:tid 140650750129920] [client 10.33.69.90:52967]     import application.modulos_python.prueba
[Mon Aug 28 15:44:48.645840 2017] [wsgi:error] [pid 4166:tid 140650750129920] [client 10.33.69.90:52967] ImportError: No module named application.modulos_python.prueba
[Mon Aug 28 15:44:48.712710 2017] [wsgi:error] [pid 4167:tid 140650750129920] [client 10.33.69.90:52970] mod_wsgi (pid=4167): Exception occurred processing WSGI script '/var/www/app/application/application.wsgi'., referer: http://10.64.17.40:8080/
[Mon Aug 28 15:44:48.712738 2017] [wsgi:error] [pid 4167:tid 140650750129920] [client 10.33.69.90:52970] Traceback (most recent call last):, referer: http://10.64.17.40:8080/
[Mon Aug 28 15:44:48.712759 2017] [wsgi:error] [pid 4167:tid 140650750129920] [client 10.33.69.90:52970]   File "/var/www/app/application/application.wsgi", line 8, in application, referer: http://10.64.17.40:8080/
[Mon Aug 28 15:44:48.712815 2017] [wsgi:error] [pid 4167:tid 140650750129920] [client 10.33.69.90:52970]     import application.modulos_python.prueba, referer: http://10.64.17.40:8080/
[Mon Aug 28 15:44:48.712835 2017] [wsgi:error] [pid 4167:tid 140650750129920] [client 10.33.69.90:52970] ImportError: No module named application.modulos_python.prueba, referer: http://10.64.17.40:8080/
[Mon Aug 28 15:48:54.668837 2017] [wsgi:error] [pid 4275:tid 139773989574400] [client 10.33.69.90:52984] mod_wsgi (pid=4275): Exception occurred processing WSGI script '/var/www/app/application/application.wsgi'.
[Mon Aug 28 15:48:54.668892 2017] [wsgi:error] [pid 4275:tid 139773989574400] [client 10.33.69.90:52984] Traceback (most recent call last):
[Mon Aug 28 15:48:54.668915 2017] [wsgi:error] [pid 4275:tid 139773989574400] [client 10.33.69.90:52984]   File "/var/www/app/application/application.wsgi", line 8, in application
[Mon Aug 28 15:48:54.668974 2017] [wsgi:error] [pid 4275:tid 139773989574400] [client 10.33.69.90:52984]     from application.modulos_python.prueba import mi_funcion
[Mon Aug 28 15:48:54.668999 2017] [wsgi:error] [pid 4275:tid 139773989574400] [client 10.33.69.90:52984] ImportError: No module named application.modulos_python.prueba
[Mon Aug 28 15:48:54.782655 2017] [wsgi:error] [pid 4276:tid 139774159890176] [client 10.33.69.90:52986] mod_wsgi (pid=4276): Exception occurred processing WSGI script '/var/www/app/application/application.wsgi'., referer: http://10.64.17.40:8080/
[Mon Aug 28 15:48:54.782695 2017] [wsgi:error] [pid 4276:tid 139774159890176] [client 10.33.69.90:52986] Traceback (most recent call last):, referer: http://10.64.17.40:8080/
[Mon Aug 28 15:48:54.782716 2017] [wsgi:error] [pid 4276:tid 139774159890176] [client 10.33.69.90:52986]   File "/var/www/app/application/application.wsgi", line 8, in application, referer: http://10.64.17.40:8080/
[Mon Aug 28 15:48:54.782775 2017] [wsgi:error] [pid 4276:tid 139774159890176] [client 10.33.69.90:52986]     from application.modulos_python.prueba import mi_funcion, referer: http://10.64.17.40:8080/
[Mon Aug 28 15:48:54.782800 2017] [wsgi:error] [pid 4276:tid 139774159890176] [client 10.33.69.90:52986] ImportError: No module named application.modulos_python.prueba, referer: http://10.64.17.40:8080/
[Mon Aug 28 15:48:55.378096 2017] [wsgi:error] [pid 4275:tid 139773972788992] [client 10.33.69.90:52985] mod_wsgi (pid=4275): Exception occurred processing WSGI script '/var/www/app/application/application.wsgi'.
[Mon Aug 28 15:48:55.378139 2017] [wsgi:error] [pid 4275:tid 139773972788992] [client 10.33.69.90:52985] Traceback (most recent call last):
[Mon Aug 28 15:48:55.378166 2017] [wsgi:error] [pid 4275:tid 139773972788992] [client 10.33.69.90:52985]   File "/var/www/app/application/application.wsgi", line 8, in application
[Mon Aug 28 15:48:55.378196 2017] [wsgi:error] [pid 4275:tid 139773972788992] [client 10.33.69.90:52985]     from application.modulos_python.prueba import mi_funcion
[Mon Aug 28 15:48:55.378218 2017] [wsgi:error] [pid 4275:tid 139773972788992] [client 10.33.69.90:52985] ImportError: No module named application.modulos_python.prueba
[Mon Aug 28 15:48:55.445337 2017] [wsgi:error] [pid 4276:tid 139774151489280] [client 10.33.69.90:52987] mod_wsgi (pid=4276): Exception occurred processing WSGI script '/var/www/app/application/application.wsgi'., referer: http://10.64.17.40:8080/
[Mon Aug 28 15:48:55.445376 2017] [wsgi:error] [pid 4276:tid 139774151489280] [client 10.33.69.90:52987] Traceback (most recent call last):, referer: http://10.64.17.40:8080/
[Mon Aug 28 15:48:55.445400 2017] [wsgi:error] [pid 4276:tid 139774151489280] [client 10.33.69.90:52987]   File "/var/www/app/application/application.wsgi", line 8, in application, referer: http://10.64.17.40:8080/
[Mon Aug 28 15:48:55.445428 2017] [wsgi:error] [pid 4276:tid 139774151489280] [client 10.33.69.90:52987]     from application.modulos_python.prueba import mi_funcion, referer: http://10.64.17.40:8080/
[Mon Aug 28 15:48:55.445460 2017] [wsgi:error] [pid 4276:tid 139774151489280] [client 10.33.69.90:52987] ImportError: No module named application.modulos_python.prueba, referer: http://10.64.17.40:8080/
[Mon Aug 28 15:48:55.802131 2017] [wsgi:error] [pid 4275:tid 139774151489280] [client 10.33.69.90:52988] mod_wsgi (pid=4275): Exception occurred processing WSGI script '/var/www/app/application/application.wsgi'.
[Mon Aug 28 15:48:55.802166 2017] [wsgi:error] [pid 4275:tid 139774151489280] [client 10.33.69.90:52988] Traceback (most recent call last):
[Mon Aug 28 15:48:55.802191 2017] [wsgi:error] [pid 4275:tid 139774151489280] [client 10.33.69.90:52988]   File "/var/www/app/application/application.wsgi", line 8, in application
[Mon Aug 28 15:48:55.802219 2017] [wsgi:error] [pid 4275:tid 139774151489280] [client 10.33.69.90:52988]     from application.modulos_python.prueba import mi_funcion
[Mon Aug 28 15:48:55.802239 2017] [wsgi:error] [pid 4275:tid 139774151489280] [client 10.33.69.90:52988] ImportError: No module named application.modulos_python.prueba
[Mon Aug 28 15:48:55.864749 2017] [wsgi:error] [pid 4276:tid 139774073501440] [client 10.33.69.90:52989] mod_wsgi (pid=4276): Exception occurred processing WSGI script '/var/www/app/application/application.wsgi'., referer: http://10.64.17.40:8080/
[Mon Aug 28 15:48:55.864798 2017] [wsgi:error] [pid 4276:tid 139774073501440] [client 10.33.69.90:52989] Traceback (most recent call last):, referer: http://10.64.17.40:8080/
[Mon Aug 28 15:48:55.864826 2017] [wsgi:error] [pid 4276:tid 139774073501440] [client 10.33.69.90:52989]   File "/var/www/app/application/application.wsgi", line 8, in application, referer: http://10.64.17.40:8080/
[Mon Aug 28 15:48:55.864855 2017] [wsgi:error] [pid 4276:tid 139774073501440] [client 10.33.69.90:52989]     from application.modulos_python.prueba import mi_funcion, referer: http://10.64.17.40:8080/
[Mon Aug 28 15:48:55.864875 2017] [wsgi:error] [pid 4276:tid 139774073501440] [client 10.33.69.90:52989] ImportError: No module named application.modulos_python.prueba, referer: http://10.64.17.40:8080/
[Mon Aug 28 19:37:41.015784 2017] [wsgi:error] [pid 2539:tid 139849541003008] [client 192.168.1.43:57641] mod_wsgi (pid=2539): Exception occurred processing WSGI script '/var/www/app/application/application.wsgi'.
[Mon Aug 28 19:37:41.015819 2017] [wsgi:error] [pid 2539:tid 139849541003008] [client 192.168.1.43:57641] Traceback (most recent call last):
[Mon Aug 28 19:37:41.015831 2017] [wsgi:error] [pid 2539:tid 139849541003008] [client 192.168.1.43:57641]   File "/var/www/app/application/application.wsgi", line 9, in application
[Mon Aug 28 19:37:41.015865 2017] [wsgi:error] [pid 2539:tid 139849541003008] [client 192.168.1.43:57641]     output = leer()
[Mon Aug 28 19:37:41.015871 2017] [wsgi:error] [pid 2539:tid 139849541003008] [client 192.168.1.43:57641]   File "/var/www/app/application/modulos_python/serieF.py", line 17, in leer
[Mon Aug 28 19:37:41.015892 2017] [wsgi:error] [pid 2539:tid 139849541003008] [client 192.168.1.43:57641]     timeout=3
[Mon Aug 28 19:37:41.015897 2017] [wsgi:error] [pid 2539:tid 139849541003008] [client 192.168.1.43:57641]   File "/usr/lib/python2.7/dist-packages/serial/serialutil.py", line 236, in __init__
[Mon Aug 28 19:37:41.016868 2017] [wsgi:error] [pid 2539:tid 139849541003008] [client 192.168.1.43:57641]     self.open()
[Mon Aug 28 19:37:41.016895 2017] [wsgi:error] [pid 2539:tid 139849541003008] [client 192.168.1.43:57641]   File "/usr/lib/python2.7/dist-packages/serial/serialposix.py", line 268, in open
[Mon Aug 28 19:37:41.018203 2017] [wsgi:error] [pid 2539:tid 139849541003008] [client 192.168.1.43:57641]     raise SerialException(msg.errno, "could not open port {}: {}".format(self._port, msg))
[Mon Aug 28 19:37:41.018233 2017] [wsgi:error] [pid 2539:tid 139849541003008] [client 192.168.1.43:57641] SerialException: [Errno 2] could not open port /dev/ttyACM0: [Errno 2] No such file or directory: '/dev/ttyACM0'
[Mon Aug 28 19:38:23.732718 2017] [wsgi:error] [pid 2690:tid 139905128720128] [client 192.168.1.43:57648] mod_wsgi (pid=2690): Exception occurred processing WSGI script '/var/www/app/application/application.wsgi'.
[Mon Aug 28 19:38:23.732766 2017] [wsgi:error] [pid 2690:tid 139905128720128] [client 192.168.1.43:57648] Traceback (most recent call last):
[Mon Aug 28 19:38:23.732778 2017] [wsgi:error] [pid 2690:tid 139905128720128] [client 192.168.1.43:57648]   File "/var/www/app/application/application.wsgi", line 9, in application
[Mon Aug 28 19:38:23.732811 2017] [wsgi:error] [pid 2690:tid 139905128720128] [client 192.168.1.43:57648]     output = leer()
[Mon Aug 28 19:38:23.732818 2017] [wsgi:error] [pid 2690:tid 139905128720128] [client 192.168.1.43:57648]   File "/var/www/app/application/modulos_python/serieF.py", line 17, in leer
[Mon Aug 28 19:38:23.732839 2017] [wsgi:error] [pid 2690:tid 139905128720128] [client 192.168.1.43:57648]     timeout=3
[Mon Aug 28 19:38:23.732844 2017] [wsgi:error] [pid 2690:tid 139905128720128] [client 192.168.1.43:57648]   File "/usr/lib/python2.7/dist-packages/serial/serialutil.py", line 236, in __init__
[Mon Aug 28 19:38:23.732943 2017] [wsgi:error] [pid 2690:tid 139905128720128] [client 192.168.1.43:57648]     self.open()
[Mon Aug 28 19:38:23.732949 2017] [wsgi:error] [pid 2690:tid 139905128720128] [client 192.168.1.43:57648]   File "/usr/lib/python2.7/dist-packages/serial/serialposix.py", line 268, in open
[Mon Aug 28 19:38:23.733066 2017] [wsgi:error] [pid 2690:tid 139905128720128] [client 192.168.1.43:57648]     raise SerialException(msg.errno, "could not open port {}: {}".format(self._port, msg))
[Mon Aug 28 19:38:23.733105 2017] [wsgi:error] [pid 2690:tid 139905128720128] [client 192.168.1.43:57648] SerialException: [Errno 2] could not open port /dev/ttyACM0: [Errno 2] No such file or directory: '/dev/ttyACM0'
[Mon Aug 28 19:39:47.399090 2017] [wsgi:error] [pid 2690:tid 139905120327424] [client 192.168.1.43:57658] mod_wsgi (pid=2690): Exception occurred processing WSGI script '/var/www/app/application/application.wsgi'.
[Mon Aug 28 19:39:47.399133 2017] [wsgi:error] [pid 2690:tid 139905120327424] [client 192.168.1.43:57658] Traceback (most recent call last):
[Mon Aug 28 19:39:47.399148 2017] [wsgi:error] [pid 2690:tid 139905120327424] [client 192.168.1.43:57658]   File "/var/www/app/application/application.wsgi", line 9, in application
[Mon Aug 28 19:39:47.399170 2017] [wsgi:error] [pid 2690:tid 139905120327424] [client 192.168.1.43:57658]     output = leer()
[Mon Aug 28 19:39:47.399176 2017] [wsgi:error] [pid 2690:tid 139905120327424] [client 192.168.1.43:57658]   File "/var/www/app/application/modulos_python/serieF.py", line 17, in leer
[Mon Aug 28 19:39:47.399186 2017] [wsgi:error] [pid 2690:tid 139905120327424] [client 192.168.1.43:57658]     timeout=3
[Mon Aug 28 19:39:47.399191 2017] [wsgi:error] [pid 2690:tid 139905120327424] [client 192.168.1.43:57658]   File "/usr/lib/python2.7/dist-packages/serial/serialutil.py", line 236, in __init__
[Mon Aug 28 19:39:47.399201 2017] [wsgi:error] [pid 2690:tid 139905120327424] [client 192.168.1.43:57658]     self.open()
[Mon Aug 28 19:39:47.399206 2017] [wsgi:error] [pid 2690:tid 139905120327424] [client 192.168.1.43:57658]   File "/usr/lib/python2.7/dist-packages/serial/serialposix.py", line 268, in open
[Mon Aug 28 19:39:47.399216 2017] [wsgi:error] [pid 2690:tid 139905120327424] [client 192.168.1.43:57658]     raise SerialException(msg.errno, "could not open port {}: {}".format(self._port, msg))
[Mon Aug 28 19:39:47.399236 2017] [wsgi:error] [pid 2690:tid 139905120327424] [client 192.168.1.43:57658] SerialException: [Errno 13] could not open port /dev/ttyACM0: [Errno 13] Permission denied: '/dev/ttyACM0'
[Mon Aug 28 19:39:48.676556 2017] [wsgi:error] [pid 2691:tid 139905120327424] [client 192.168.1.43:57659] mod_wsgi (pid=2691): Exception occurred processing WSGI script '/var/www/app/application/application.wsgi'.
[Mon Aug 28 19:39:48.676591 2017] [wsgi:error] [pid 2691:tid 139905120327424] [client 192.168.1.43:57659] Traceback (most recent call last):
[Mon Aug 28 19:39:48.676602 2017] [wsgi:error] [pid 2691:tid 139905120327424] [client 192.168.1.43:57659]   File "/var/www/app/application/application.wsgi", line 9, in application
[Mon Aug 28 19:39:48.676641 2017] [wsgi:error] [pid 2691:tid 139905120327424] [client 192.168.1.43:57659]     output = leer()
[Mon Aug 28 19:39:48.676647 2017] [wsgi:error] [pid 2691:tid 139905120327424] [client 192.168.1.43:57659]   File "/var/www/app/application/modulos_python/serieF.py", line 17, in leer
[Mon Aug 28 19:39:48.676666 2017] [wsgi:error] [pid 2691:tid 139905120327424] [client 192.168.1.43:57659]     timeout=3
[Mon Aug 28 19:39:48.676671 2017] [wsgi:error] [pid 2691:tid 139905120327424] [client 192.168.1.43:57659]   File "/usr/lib/python2.7/dist-packages/serial/serialutil.py", line 236, in __init__
[Mon Aug 28 19:39:48.676756 2017] [wsgi:error] [pid 2691:tid 139905120327424] [client 192.168.1.43:57659]     self.open()
[Mon Aug 28 19:39:48.676761 2017] [wsgi:error] [pid 2691:tid 139905120327424] [client 192.168.1.43:57659]   File "/usr/lib/python2.7/dist-packages/serial/serialposix.py", line 268, in open
[Mon Aug 28 19:39:48.676862 2017] [wsgi:error] [pid 2691:tid 139905120327424] [client 192.168.1.43:57659]     raise SerialException(msg.errno, "could not open port {}: {}".format(self._port, msg))
[Mon Aug 28 19:39:48.676872 2017] [wsgi:error] [pid 2691:tid 139905120327424] [client 192.168.1.43:57659] SerialException: [Errno 13] could not open port /dev/ttyACM0: [Errno 13] Permission denied: '/dev/ttyACM0'
[Mon Aug 28 20:20:52.550894 2017] [wsgi:error] [pid 2835:tid 139958060828416] [client 192.168.1.43:60263] mod_wsgi (pid=2835): Exception occurred processing WSGI script '/var/www/app/application/application.wsgi'.
[Mon Aug 28 20:20:52.550991 2017] [wsgi:error] [pid 2835:tid 139958060828416] [client 192.168.1.43:60263] Traceback (most recent call last):
[Mon Aug 28 20:20:52.551049 2017] [wsgi:error] [pid 2835:tid 139958060828416] [client 192.168.1.43:60263]   File "/var/www/app/application/application.wsgi", line 8, in application
[Mon Aug 28 20:20:52.551467 2017] [wsgi:error] [pid 2835:tid 139958060828416] [client 192.168.1.43:60263]     from application.modulos_python.serieF import leer
[Mon Aug 28 20:20:52.551621 2017] [wsgi:error] [pid 2835:tid 139958060828416] [client 192.168.1.43:60263]   File "/var/www/app/application/modulos_python/serieF.py", line 41
[Mon Aug 28 20:20:52.551628 2017] [wsgi:error] [pid 2835:tid 139958060828416] [client 192.168.1.43:60263]     out3 = out3 + "/"+ d
[Mon Aug 28 20:20:52.551631 2017] [wsgi:error] [pid 2835:tid 139958060828416] [client 192.168.1.43:60263]        ^
[Mon Aug 28 20:20:52.551634 2017] [wsgi:error] [pid 2835:tid 139958060828416] [client 192.168.1.43:60263] IndentationError: expected an indented block
[Mon Aug 28 20:20:54.541957 2017] [wsgi:error] [pid 2836:tid 139958060828416] [client 192.168.1.43:60264] mod_wsgi (pid=2836): Exception occurred processing WSGI script '/var/www/app/application/application.wsgi'.
[Mon Aug 28 20:20:54.541999 2017] [wsgi:error] [pid 2836:tid 139958060828416] [client 192.168.1.43:60264] Traceback (most recent call last):
[Mon Aug 28 20:20:54.542012 2017] [wsgi:error] [pid 2836:tid 139958060828416] [client 192.168.1.43:60264]   File "/var/www/app/application/application.wsgi", line 8, in application
[Mon Aug 28 20:20:54.542038 2017] [wsgi:error] [pid 2836:tid 139958060828416] [client 192.168.1.43:60264]     from application.modulos_python.serieF import leer
[Mon Aug 28 20:20:54.542061 2017] [wsgi:error] [pid 2836:tid 139958060828416] [client 192.168.1.43:60264]   File "/var/www/app/application/modulos_python/serieF.py", line 41
[Mon Aug 28 20:20:54.542064 2017] [wsgi:error] [pid 2836:tid 139958060828416] [client 192.168.1.43:60264]     out3 = out3 + "/"+ d
[Mon Aug 28 20:20:54.542066 2017] [wsgi:error] [pid 2836:tid 139958060828416] [client 192.168.1.43:60264]        ^
[Mon Aug 28 20:20:54.542068 2017] [wsgi:error] [pid 2836:tid 139958060828416] [client 192.168.1.43:60264] IndentationError: expected an indented block
[Mon Aug 28 20:20:55.914255 2017] [wsgi:error] [pid 2835:tid 139958052435712] [client 192.168.1.43:60265] mod_wsgi (pid=2835): Exception occurred processing WSGI script '/var/www/app/application/application.wsgi'.
[Mon Aug 28 20:20:55.914411 2017] [wsgi:error] [pid 2835:tid 139958052435712] [client 192.168.1.43:60265] Traceback (most recent call last):
[Mon Aug 28 20:20:55.914473 2017] [wsgi:error] [pid 2835:tid 139958052435712] [client 192.168.1.43:60265]   File "/var/www/app/application/application.wsgi", line 8, in application
[Mon Aug 28 20:20:55.914546 2017] [wsgi:error] [pid 2835:tid 139958052435712] [client 192.168.1.43:60265]     from application.modulos_python.serieF import leer
[Mon Aug 28 20:20:55.914653 2017] [wsgi:error] [pid 2835:tid 139958052435712] [client 192.168.1.43:60265]   File "/var/www/app/application/modulos_python/serieF.py", line 41
[Mon Aug 28 20:20:55.914854 2017] [wsgi:error] [pid 2835:tid 139958052435712] [client 192.168.1.43:60265]     out3 = out3 + "/"+ d
[Mon Aug 28 20:20:55.914882 2017] [wsgi:error] [pid 2835:tid 139958052435712] [client 192.168.1.43:60265]        ^
[Mon Aug 28 20:20:55.914895 2017] [wsgi:error] [pid 2835:tid 139958052435712] [client 192.168.1.43:60265] IndentationError: expected an indented block
[Tue Aug 29 21:24:51.358335 2017] [wsgi:error] [pid 17892:tid 1973417008] [client 192.168.1.43:63781] mod_wsgi (pid=17892): Exception occurred processing WSGI script '/var/www/app/application/application.wsgi'.
[Tue Aug 29 21:24:51.358656 2017] [wsgi:error] [pid 17892:tid 1973417008] [client 192.168.1.43:63781] Traceback (most recent call last):
[Tue Aug 29 21:24:51.358787 2017] [wsgi:error] [pid 17892:tid 1973417008] [client 192.168.1.43:63781]   File "/var/www/app/application/application.wsgi", line 9, in application
[Tue Aug 29 21:24:51.359143 2017] [wsgi:error] [pid 17892:tid 1973417008] [client 192.168.1.43:63781]     output = leer()
[Tue Aug 29 21:24:51.359225 2017] [wsgi:error] [pid 17892:tid 1973417008] [client 192.168.1.43:63781]   File "/var/www/app/application/modulos_python/serieF.py", line 17, in leer
[Tue Aug 29 21:24:51.359567 2017] [wsgi:error] [pid 17892:tid 1973417008] [client 192.168.1.43:63781]     timeout=3
[Tue Aug 29 21:24:51.359657 2017] [wsgi:error] [pid 17892:tid 1973417008] [client 192.168.1.43:63781]   File "/usr/lib/python2.7/dist-packages/serial/serialutil.py", line 236, in __init__
[Tue Aug 29 21:24:51.361030 2017] [wsgi:error] [pid 17892:tid 1973417008] [client 192.168.1.43:63781]     self.open()
[Tue Aug 29 21:24:51.361111 2017] [wsgi:error] [pid 17892:tid 1973417008] [client 192.168.1.43:63781]   File "/usr/lib/python2.7/dist-packages/serial/serialposix.py", line 268, in open
[Tue Aug 29 21:24:51.362874 2017] [wsgi:error] [pid 17892:tid 1973417008] [client 192.168.1.43:63781]     raise SerialException(msg.errno, "could not open port {}: {}".format(self._port, msg))
[Tue Aug 29 21:24:51.363080 2017] [wsgi:error] [pid 17892:tid 1973417008] [client 192.168.1.43:63781] SerialException: [Errno 13] could not open port /dev/ttyACM0: [Errno 13] Permission denied: '/dev/ttyACM0'
[Tue Aug 29 21:24:51.687549 2017] [wsgi:error] [pid 17892:tid 1965028400] [client 192.168.1.43:63782] mod_wsgi (pid=17892): Exception occurred processing WSGI script '/var/www/app/application/application.wsgi'., referer: http://192.168.1.48:8080/
[Tue Aug 29 21:24:51.687667 2017] [wsgi:error] [pid 17892:tid 1965028400] [client 192.168.1.43:63782] Traceback (most recent call last):, referer: http://192.168.1.48:8080/
[Tue Aug 29 21:24:51.687737 2017] [wsgi:error] [pid 17892:tid 1965028400] [client 192.168.1.43:63782]   File "/var/www/app/application/application.wsgi", line 9, in application, referer: http://192.168.1.48:8080/
[Tue Aug 29 21:24:51.687832 2017] [wsgi:error] [pid 17892:tid 1965028400] [client 192.168.1.43:63782]     output = leer(), referer: http://192.168.1.48:8080/
[Tue Aug 29 21:24:51.687872 2017] [wsgi:error] [pid 17892:tid 1965028400] [client 192.168.1.43:63782]   File "/var/www/app/application/modulos_python/serieF.py", line 17, in leer, referer: http://192.168.1.48:8080/
[Tue Aug 29 21:24:51.687939 2017] [wsgi:error] [pid 17892:tid 1965028400] [client 192.168.1.43:63782]     timeout=3, referer: http://192.168.1.48:8080/
[Tue Aug 29 21:24:51.688009 2017] [wsgi:error] [pid 17892:tid 1965028400] [client 192.168.1.43:63782]   File "/usr/lib/python2.7/dist-packages/serial/serialutil.py", line 236, in __init__, referer: http://192.168.1.48:8080/
[Tue Aug 29 21:24:51.688076 2017] [wsgi:error] [pid 17892:tid 1965028400] [client 192.168.1.43:63782]     self.open(), referer: http://192.168.1.48:8080/
[Tue Aug 29 21:24:51.688112 2017] [wsgi:error] [pid 17892:tid 1965028400] [client 192.168.1.43:63782]   File "/usr/lib/python2.7/dist-packages/serial/serialposix.py", line 268, in open, referer: http://192.168.1.48:8080/
[Tue Aug 29 21:24:51.688176 2017] [wsgi:error] [pid 17892:tid 1965028400] [client 192.168.1.43:63782]     raise SerialException(msg.errno, "could not open port {}: {}".format(self._port, msg)), referer: http://192.168.1.48:8080/
[Tue Aug 29 21:24:51.688243 2017] [wsgi:error] [pid 17892:tid 1965028400] [client 192.168.1.43:63782] SerialException: [Errno 13] could not open port /dev/ttyACM0: [Errno 13] Permission denied: '/dev/ttyACM0', referer: http://192.168.1.48:8080/
[Tue Aug 29 21:28:34.518615 2017] [wsgi:error] [pid 17892:tid 1906308144] [client 192.168.1.41:41557] mod_wsgi (pid=17892): Exception occurred processing WSGI script '/var/www/app/application/application.wsgi'.
[Tue Aug 29 21:28:34.518819 2017] [wsgi:error] [pid 17892:tid 1906308144] [client 192.168.1.41:41557] Traceback (most recent call last):
[Tue Aug 29 21:28:34.518943 2017] [wsgi:error] [pid 17892:tid 1906308144] [client 192.168.1.41:41557]   File "/var/www/app/application/application.wsgi", line 9, in application
[Tue Aug 29 21:28:34.519131 2017] [wsgi:error] [pid 17892:tid 1906308144] [client 192.168.1.41:41557]     output = leer()
[Tue Aug 29 21:28:34.519210 2017] [wsgi:error] [pid 17892:tid 1906308144] [client 192.168.1.41:41557]   File "/var/www/app/application/modulos_python/serieF.py", line 38, in leer
[Tue Aug 29 21:28:34.519340 2017] [wsgi:error] [pid 17892:tid 1906308144] [client 192.168.1.41:41557]     out2 =[hex(ord(c)) for c in out]
[Tue Aug 29 21:28:34.519461 2017] [wsgi:error] [pid 17892:tid 1906308144] [client 192.168.1.41:41557] UnboundLocalError: local variable 'out' referenced before assignment
[Tue Aug 29 21:28:38.471957 2017] [wsgi:error] [pid 17892:tid 1872753712] [client 192.168.1.41:41560] mod_wsgi (pid=17892): Exception occurred processing WSGI script '/var/www/app/application/application.wsgi'.
[Tue Aug 29 21:28:38.472232 2017] [wsgi:error] [pid 17892:tid 1872753712] [client 192.168.1.41:41560] Traceback (most recent call last):
[Tue Aug 29 21:28:38.472362 2017] [wsgi:error] [pid 17892:tid 1872753712] [client 192.168.1.41:41560]   File "/var/www/app/application/application.wsgi", line 9, in application
[Tue Aug 29 21:28:38.472555 2017] [wsgi:error] [pid 17892:tid 1872753712] [client 192.168.1.41:41560]     output = leer()
[Tue Aug 29 21:28:38.472635 2017] [wsgi:error] [pid 17892:tid 1872753712] [client 192.168.1.41:41560]   File "/var/www/app/application/modulos_python/serieF.py", line 38, in leer
[Tue Aug 29 21:28:38.472764 2017] [wsgi:error] [pid 17892:tid 1872753712] [client 192.168.1.41:41560]     out2 =[hex(ord(c)) for c in out]
[Tue Aug 29 21:28:38.472887 2017] [wsgi:error] [pid 17892:tid 1872753712] [client 192.168.1.41:41560] UnboundLocalError: local variable 'out' referenced before assignment
[Tue Aug 29 21:28:39.616045 2017] [wsgi:error] [pid 17892:tid 1864365104] [client 192.168.1.41:41561] mod_wsgi (pid=17892): Exception occurred processing WSGI script '/var/www/app/application/application.wsgi'., referer: http://192.168.1.48:8080/
[Tue Aug 29 21:28:39.616315 2017] [wsgi:error] [pid 17892:tid 1864365104] [client 192.168.1.41:41561] Traceback (most recent call last):, referer: http://192.168.1.48:8080/
[Tue Aug 29 21:28:39.616447 2017] [wsgi:error] [pid 17892:tid 1864365104] [client 192.168.1.41:41561]   File "/var/www/app/application/application.wsgi", line 9, in application, referer: http://192.168.1.48:8080/
[Tue Aug 29 21:28:39.616639 2017] [wsgi:error] [pid 17892:tid 1864365104] [client 192.168.1.41:41561]     output = leer(), referer: http://192.168.1.48:8080/
[Tue Aug 29 21:28:39.616770 2017] [wsgi:error] [pid 17892:tid 1864365104] [client 192.168.1.41:41561]   File "/var/www/app/application/modulos_python/serieF.py", line 38, in leer, referer: http://192.168.1.48:8080/
[Tue Aug 29 21:28:39.616902 2017] [wsgi:error] [pid 17892:tid 1864365104] [client 192.168.1.41:41561]     out2 =[hex(ord(c)) for c in out], referer: http://192.168.1.48:8080/
[Tue Aug 29 21:28:39.617026 2017] [wsgi:error] [pid 17892:tid 1864365104] [client 192.168.1.41:41561] UnboundLocalError: local variable 'out' referenced before assignment, referer: http://192.168.1.48:8080/
[Tue Aug 29 23:14:11.257431 2017] [wsgi:error] [pid 19277:tid 1973417008] [client 192.168.1.43:49396] mod_wsgi (pid=19277): Exception occurred processing WSGI script '/var/www/app/application/application.wsgi'.
[Tue Aug 29 23:14:11.257694 2017] [wsgi:error] [pid 19277:tid 1973417008] [client 192.168.1.43:49396] Traceback (most recent call last):
[Tue Aug 29 23:14:11.257773 2017] [wsgi:error] [pid 19277:tid 1973417008] [client 192.168.1.43:49396]   File "/var/www/app/application/application.wsgi", line 8, in application
[Tue Aug 29 23:14:11.257964 2017] [wsgi:error] [pid 19277:tid 1973417008] [client 192.168.1.43:49396]     from application.modulos_python.serieF import leer
[Tue Aug 29 23:14:11.258060 2017] [wsgi:error] [pid 19277:tid 1973417008] [client 192.168.1.43:49396]   File "/var/www/app/application/modulos_python/serieF.py", line 48
[Tue Aug 29 23:14:11.258090 2017] [wsgi:error] [pid 19277:tid 1973417008] [client 192.168.1.43:49396] SyntaxError: Non-ASCII character '\\xc3' in file /var/www/app/application/modulos_python/serieF.py on line 48, but no encoding declared; see http://python.org/dev/peps/pep-0263/ for details
[Tue Aug 29 23:14:11.490427 2017] [wsgi:error] [pid 19277:tid 1965028400] [client 192.168.1.43:49397] mod_wsgi (pid=19277): Exception occurred processing WSGI script '/var/www/app/application/application.wsgi'., referer: http://192.168.1.48:8080/
[Tue Aug 29 23:14:11.490570 2017] [wsgi:error] [pid 19277:tid 1965028400] [client 192.168.1.43:49397] Traceback (most recent call last):, referer: http://192.168.1.48:8080/
[Tue Aug 29 23:14:11.490647 2017] [wsgi:error] [pid 19277:tid 1965028400] [client 192.168.1.43:49397]   File "/var/www/app/application/application.wsgi", line 8, in application, referer: http://192.168.1.48:8080/
[Tue Aug 29 23:14:11.490755 2017] [wsgi:error] [pid 19277:tid 1965028400] [client 192.168.1.43:49397]     from application.modulos_python.serieF import leer, referer: http://192.168.1.48:8080/
[Tue Aug 29 23:14:11.490844 2017] [wsgi:error] [pid 19277:tid 1965028400] [client 192.168.1.43:49397]   File "/var/www/app/application/modulos_python/serieF.py", line 48, referer: http://192.168.1.48:8080/
[Tue Aug 29 23:14:11.490873 2017] [wsgi:error] [pid 19277:tid 1965028400] [client 192.168.1.43:49397] SyntaxError: Non-ASCII character '\\xc3' in file /var/www/app/application/modulos_python/serieF.py on line 48, but no encoding declared; see http://python.org/dev/peps/pep-0263/ for details, referer: http://192.168.1.48:8080/
[Tue Aug 29 23:16:29.636045 2017] [wsgi:error] [pid 19356:tid 1974465584] [client 192.168.1.43:49399] Content-type: text/html
[Tue Aug 29 23:16:29.636306 2017] [wsgi:error] [pid 19356:tid 1974465584] [client 192.168.1.43:49399] 
[Tue Aug 29 23:16:29.636385 2017] [wsgi:error] [pid 19356:tid 1974465584] [client 192.168.1.43:49399] <html>
[Tue Aug 29 23:16:29.636460 2017] [wsgi:error] [pid 19356:tid 1974465584] [client 192.168.1.43:49399] <body>
[Tue Aug 29 23:16:29.636532 2017] [wsgi:error] [pid 19356:tid 1974465584] [client 192.168.1.43:49399] <p>Aqui esta la lectura:</p>
[Tue Aug 29 23:16:29.636604 2017] [wsgi:error] [pid 19356:tid 1974465584] [client 192.168.1.43:49399] <ul>
[Tue Aug 29 23:16:29.636688 2017] [wsgi:error] [pid 19356:tid 1974465584] [client 192.168.1.43:49399] <li>La lectura es: "Lectura: /0x1/0x2/0x20/0x0/0x22".</li>
[Tue Aug 29 23:16:29.636805 2017] [wsgi:error] [pid 19356:tid 1974465584] [client 192.168.1.43:49399] </ul>
[Tue Aug 29 23:16:29.636885 2017] [wsgi:error] [pid 19356:tid 1974465584] [client 192.168.1.43:49399] </body>
[Tue Aug 29 23:16:29.636953 2017] [wsgi:error] [pid 19356:tid 1974465584] [client 192.168.1.43:49399] </html>
[Tue Aug 29 23:16:33.951601 2017] [wsgi:error] [pid 19356:tid 1966076976] [client 192.168.1.43:49399] Content-type: text/html, referer: http://192.168.1.48:8080/
[Tue Aug 29 23:16:33.951775 2017] [wsgi:error] [pid 19356:tid 1966076976] [client 192.168.1.43:49399] , referer: http://192.168.1.48:8080/
[Tue Aug 29 23:16:33.951850 2017] [wsgi:error] [pid 19356:tid 1966076976] [client 192.168.1.43:49399] <html>, referer: http://192.168.1.48:8080/
[Tue Aug 29 23:16:33.951922 2017] [wsgi:error] [pid 19356:tid 1966076976] [client 192.168.1.43:49399] <body>, referer: http://192.168.1.48:8080/
[Tue Aug 29 23:16:33.951995 2017] [wsgi:error] [pid 19356:tid 1966076976] [client 192.168.1.43:49399] <p>Aqui esta la lectura:</p>, referer: http://192.168.1.48:8080/
[Tue Aug 29 23:16:33.952068 2017] [wsgi:error] [pid 19356:tid 1966076976] [client 192.168.1.43:49399] <ul>, referer: http://192.168.1.48:8080/
[Tue Aug 29 23:16:33.952151 2017] [wsgi:error] [pid 19356:tid 1966076976] [client 192.168.1.43:49399] <li>La lectura es: "Lectura: /0x1/0x2/0x20/0x0/0x22".</li>, referer: http://192.168.1.48:8080/
[Tue Aug 29 23:16:33.952233 2017] [wsgi:error] [pid 19356:tid 1966076976] [client 192.168.1.43:49399] </ul>, referer: http://192.168.1.48:8080/
[Tue Aug 29 23:16:33.952305 2017] [wsgi:error] [pid 19356:tid 1966076976] [client 192.168.1.43:49399] </body>, referer: http://192.168.1.48:8080/
[Tue Aug 29 23:16:33.952391 2017] [wsgi:error] [pid 19356:tid 1966076976] [client 192.168.1.43:49399] </html>, referer: http://192.168.1.48:8080/
